<?xml version = "1.0"?>
<robot xmlns:xacro="http://www.ros.org/wiki.xacro" name = "robot" >

<xacro:include filename="inertial.xacro"/>
<xacro:include filename="lidar.xacro"/>
<xacro:include filename="stereo.xacro"/>
<xacro:include filename="gps.xacro"/>
<xacro:include filename="imu.xacro"/>
<xacro:include filename="cam.xacro"/>

<xacro:property name="wheel_radius" value="0.1"/>
<xacro:property name="wheel_length" value="0.05"/>
<xacro:property name="wheel_mass" value="0.5"/>
<xacro:property name="damping" value="0.1"/>
<xacro:property name="friction" value="0.5"/>

    <material name = "grey">
        <color rgba = "0.7 0.7 0.7 1" />
    </material>

    <material name = "green">
        <color rgba = "0 0.6 0 1" />
    </material>

    <material name = "white">
        <color rgba = "1 1 1 1" />
    </material>

    <material name = "black">
        <color rgba = "0 0 0 1" />
    </material>

    <material name = "yellow">
        <color rgba = "0.7 0.9 0 1" />
    </material>

    <material name="orange">
    <color rgba="1 0.65 0 1" />
    </material>

    <link name="base_footprint">
        <inertial>
            <mass value="0.0"/>
            <origin xyz="0 0 0" rpy="0 0 0"/>
            <inertia ixx="0" ixy="0" ixz="0" iyy="0" iyz="0" izz="0"/>

        </inertial>
    </link>

    <joint name="base_joint" type="fixed">
        <parent link="base_footprint"/>
        <child link="base_link"/>
        <origin xyz = "0 0 0.05" rpy = "0 0 0" />

    </joint>
    
    
    <link name = "base_link">
        <visual>
            <geometry>
                <box size = "0.6 0.4 0.2" />
            </geometry>
            <origin xyz = "0 0 0.1" rpy = "0 0 0" />
            <material name = "orange" />
        </visual>

        <collision>
            <geometry>
                <box size = "0.6 0.4 0.2" />
            </geometry>
            <origin xyz = "0 0 0.1" rpy = "0 0 0" />
        </collision>

        <xacro:inertial_box mass="10" x="0.6" y="0.4" z="0.2">
            <origin xyz="0 0 0.1" rpy="0 0 0"/>
        </xacro:inertial_box>
    </link>

    <gazebo reference="base_link">
        <material>Gazebo/Orange</material>
    </gazebo>


   
    <link name="left_wheel_back_link">
        <visual>
            <geometry>
                <cylinder radius="0.1" length="0.05" />
            </geometry>

            <origin xyz="0 0 0" rpy="1.57 0 0"/>
            <material name = "white" />
        </visual>

        <collision>
            <geometry>
                <cylinder radius="0.1" length="0.05" />
            </geometry>

            <origin xyz="0 0 0" rpy="1.57 0 0"/>
        </collision>

        <xacro:inertial_cylinder mass="10" length="0.05" radius="0.1">
            <origin xyz="0 0 0" rpy="1.57 0 0"/>
        </xacro:inertial_cylinder>
    </link>

    <gazebo reference="left_wheel_back_link">
        <material>Gazebo/White</material>
    </gazebo>

     

    <joint name="base_left_wheel_back_joint" type="continuous">
        <parent link="base_link" />
        <child link="left_wheel_back_link" />
        <origin xyz="-0.15 0.225 0" rpy="0 0 0"/>
        <axis xyz="0 1 0" />
        <dynamics damping="0.1" friction="0.5"/>
    </joint>

    <link name="right_wheel_back_link">
        <visual>
            <geometry>
                <cylinder radius="0.1" length="0.05" />
            </geometry>

            <origin xyz="0 0 0" rpy="-1.57 0 0"/>
            <material name = "white" />
        </visual>

        <collision>
            <geometry>
                <cylinder radius="0.1" length="0.05" />
            </geometry>

            <origin xyz="0 0 0" rpy="-1.57 0 0"/>
        </collision>

        <xacro:inertial_cylinder mass="10" length="0.05" radius="0.1">
            <origin xyz="0 0 0" rpy="-1.57 0 0"/>
        </xacro:inertial_cylinder>
    </link>

    <gazebo reference="right_wheel_back_link">
        <material>Gazebo/White</material>
    </gazebo>

    <joint name="base_right_wheel_back_joint" type="continuous">
        <parent link="base_link" />
        <child link="right_wheel_back_link" />
        <origin xyz="-0.15 -0.225 0" rpy="0 0 0"/>
        <axis xyz="0 1 0" />
        <dynamics damping="0.1" friction="0.5"/>
    </joint>

     <link name="left_wheel_front_link">
        <visual>
            <geometry>
                <cylinder radius="0.1" length="0.05" />
            </geometry>

            <origin xyz="0 0 0" rpy="1.57 0 0"/>
            <material name = "white" />
        </visual>

        <collision>
            <geometry>
                <cylinder radius="0.1" length="0.05" />
            </geometry>

            <origin xyz="0 0 0" rpy="1.57 0 0"/>
        </collision>

        <xacro:inertial_cylinder mass="10" length="0.05" radius="0.1">
            <origin xyz="0 0 0" rpy="1.57 0 0"/>
        </xacro:inertial_cylinder>
    </link>

    <gazebo reference="left_wheel_front_link">
        <material>Gazebo/White</material>
    </gazebo>

     

    <joint name="base_left_wheel_front_joint" type="continuous">
        <parent link="base_link" />
        <child link="left_wheel_front_link" />
        <origin xyz="0.15 0.225 0" rpy="0 0 0"/>
        <axis xyz="0 1 0" />
        <dynamics damping="0.1" friction="0.5"/>
    </joint>


    <link name="right_wheel_front_link">
        <visual>
            <geometry>
                <cylinder radius="0.1" length="0.05" />
            </geometry>

            <origin xyz="0 0 0" rpy="-1.57 0 0"/>
            <material name = "white" />
        </visual>

        <collision>
            <geometry>
                <cylinder radius="0.1" length="0.05" />
            </geometry>

            <origin xyz="0 0 0" rpy="-1.57 0 0"/>
        </collision>

        <xacro:inertial_cylinder mass="10" length="0.05" radius="0.1">
            <origin xyz="0 0 0" rpy="-1.57 0 0"/>
        </xacro:inertial_cylinder>
    </link>

    <gazebo reference="left_wheel_front_link">
        <material>Gazebo/White</material>
    </gazebo>

    <joint name="base_right_wheel_front_joint" type="continuous">
        <parent link="base_link" />
        <child link="right_wheel_front_link" />
        <origin xyz="0.15 -0.225 0" rpy="0 0 0"/>
        <axis xyz="0 1 0" />
        <dynamics damping="0.1" friction="0.5"/>
    </joint>

     <gazebo>
        <plugin name='diff_drive' filename='libgazebo_ros_diff_drive.so'>
            <num_wheel_pairs>2</num_wheel_pairs>

            <!-- wheels -->
            <left_joint>base_left_wheel_front_joint</left_joint>
            
            <right_joint>base_right_wheel_front_joint</right_joint>
           
           <left_joint>base_left_wheel_back_joint</left_joint>
            
            <right_joint>base_right_wheel_back_joint</right_joint>

            <!-- kinematics -->
            <wheel_separation>0.45</wheel_separation>
            <wheel_diameter>0.2</wheel_diameter>

            <!-- limits -->
            <max_wheel_torque>10</max_wheel_torque>
            <max_wheel_acceleration>1.0</max_wheel_acceleration>

            <!-- output -->
            <publish_odom>true</publish_odom>
            <publish_odom_tf>true</publish_odom_tf>
            <publish_wheel_tf>false</publish_wheel_tf>

            <odometry_frame>odom</odometry_frame>
            <robot_base_frame>base_footprint</robot_base_frame>
        </plugin>
    </gazebo>

    <gazebo>
        <plugin name="gazebo_ros_joint_state_publisher" filename="libgazebo_ros_joint_state_publisher.so">
            <update_rate>10</update_rate>
            <joint_name>base_left_wheel_front_joint</joint_name>
            <joint_name>base_left_wheel_back_joint</joint_name>
            <joint_name>base_right_wheel_front_joint</joint_name>
            <joint_name>base_right_wheel_back_joint</joint_name>
            
        </plugin>
    </gazebo>

</robot>
