<?xml version="1.0" ?>
<!-- =================================================================================== -->
<!-- |    This document was autogenerated by xacro from marsyard2022.world.xacro       | -->
<!-- |    EDITING THIS FILE BY HAND IS NOT RECOMMENDED                                 | -->
<!-- =================================================================================== -->
<sdf version="1.7">
  <world name="default">
    <light name="sun" type="directional">
      <cast_shadows>1</cast_shadows>
      <pose>0 0 10 0 -0 0</pose>
      <diffuse>0.8 0.8 0.8 1</diffuse>
      <specular>0.2 0.2 0.2 1</specular>
      <attenuation>
        <range>1000</range>
        <constant>0.9</constant>
        <linear>0.01</linear>
        <quadratic>0.001</quadratic>
      </attenuation>
      <direction>-0.5 0.1 -0.9</direction>
      <spot>
        <inner_angle>0</inner_angle>
        <outer_angle>0</outer_angle>
        <falloff>0</falloff>
      </spot>
    </light>
    <model name="ground_plane">
      <static>1</static>
      <link name="link">
        <collision name="collision">
          <geometry>
            <plane>
              <normal>0 0 1</normal>
              <size>100 100</size>
            </plane>
          </geometry>
          <surface>
            <contact>
              <collide_bitmask>65535</collide_bitmask>
              <ode/>
            </contact>
            <friction>
              <ode>
                <mu>100</mu>
                <mu2>50</mu2>
              </ode>
              <torsional>
                <ode/>
              </torsional>
            </friction>
            <bounce/>
          </surface>
          <max_contacts>10</max_contacts>
        </collision>
        <visual name="visual">
          <cast_shadows>0</cast_shadows>
          <geometry>
            <plane>
              <normal>0 0 1</normal>
              <size>100 100</size>
            </plane>
          </geometry>
          <material>
            <script>
              <uri>file://media/materials/scripts/gazebo.material</uri>
              <name>Gazebo/Grey</name>
            </script>
          </material>
        </visual>
        <self_collide>0</self_collide>
        <enable_wind>0</enable_wind>
        <kinematic>0</kinematic>
      </link>
    </model>
    <gravity>0 0 -9.8</gravity>
    <magnetic_field>6e-06 2.3e-05 -4.2e-05</magnetic_field>
    <atmosphere type="adiabatic"/>
    <physics type="ode">
      <max_step_size>0.001</max_step_size>
      <real_time_factor>1</real_time_factor>
      <real_time_update_rate>1000</real_time_update_rate>
    </physics>
    <scene>
      <ambient>0.4 0.4 0.4 1</ambient>
      <background>0.7 0.7 0.7 1</background>
      <shadows>1</shadows>
    </scene>
    <audio>
      <device>default</device>
    </audio>
    <wind/>
    <spherical_coordinates>
      <surface_model>EARTH_WGS84</surface_model>
      <latitude_deg>0</latitude_deg>
      <longitude_deg>0</longitude_deg>
      <elevation>0</elevation>
      <heading_deg>0</heading_deg>
    </spherical_coordinates>
    <model name="my_robot">
      <link name="base_footprint">
        <inertial>
          <pose>0.004175 0 0.155702 0 -0 0</pose>
          <mass>10.54</mass>
          <inertia>
            <ixx>0.180019</ixx>
            <ixy>0</ixy>
            <ixz>-0.00883411</ixz>
            <iyy>0.373902</iyy>
            <iyz>0</iyz>
            <izz>0.461031</izz>
          </inertia>
        </inertial>
        <collision name="base_footprint_fixed_joint_lump__base_link_collision">
          <pose>0 0 0.15 0 -0 0</pose>
          <geometry>
            <box>
              <size>0.6 0.4 0.2</size>
            </box>
          </geometry>
          <surface>
            <contact>
              <ode/>
            </contact>
            <friction>
              <ode/>
              <torsional>
                <ode/>
              </torsional>
            </friction>
            <bounce/>
          </surface>
          <max_contacts>10</max_contacts>
        </collision>
        <collision name="base_footprint_fixed_joint_lump__gps_link_collision_1">
          <pose>-0.25 0 0.26 0 -0 0</pose>
          <geometry>
            <cylinder>
              <length>0.04</length>
              <radius>0.05</radius>
            </cylinder>
          </geometry>
          <surface>
            <contact>
              <ode/>
            </contact>
            <friction>
              <ode/>
              <torsional>
                <ode/>
              </torsional>
            </friction>
            <bounce/>
          </surface>
          <max_contacts>10</max_contacts>
        </collision>
        <collision name="base_footprint_fixed_joint_lump__imu_link_collision_2">
          <pose>0 0 0.05 0 -0 0</pose>
          <geometry>
            <cylinder>
              <length>0.04</length>
              <radius>0.05</radius>
            </cylinder>
          </geometry>
          <surface>
            <contact>
              <ode/>
            </contact>
            <friction>
              <ode/>
              <torsional>
                <ode/>
              </torsional>
            </friction>
            <bounce/>
          </surface>
          <max_contacts>10</max_contacts>
        </collision>
        <collision name="base_footprint_fixed_joint_lump__lidar_stand_collision_3">
          <pose>0.15 0 0.3 0 -0 0</pose>
          <geometry>
            <cylinder>
              <length>0.15</length>
              <radius>0.03</radius>
            </cylinder>
          </geometry>
          <max_contacts>10</max_contacts>
          <surface>
            <contact>
              <ode/>
            </contact>
            <bounce/>
            <friction>
              <torsional>
                <ode/>
              </torsional>
              <ode/>
            </friction>
          </surface>
        </collision>
        <collision name="base_footprint_fixed_joint_lump__laser_frame_collision_4">
          <pose>0.15 0 0.375 0 -0 0</pose>
          <geometry>
            <cylinder>
              <length>0.04</length>
              <radius>0.05</radius>
            </cylinder>
          </geometry>
          <surface>
            <contact>
              <ode/>
            </contact>
            <friction>
              <ode/>
              <torsional>
                <ode/>
              </torsional>
            </friction>
            <bounce/>
          </surface>
          <max_contacts>10</max_contacts>
        </collision>
        <visual name="base_footprint_fixed_joint_lump__base_link_visual">
          <pose>0 0 0.15 0 -0 0</pose>
          <geometry>
            <box>
              <size>0.6 0.4 0.2</size>
            </box>
          </geometry>
          <material>
            <script>
              <name>Gazebo/Orange</name>
              <uri>file://media/materials/scripts/gazebo.material</uri>
            </script>
          </material>
        </visual>
        <visual name="base_footprint_fixed_joint_lump__camera_link_visual_1">
          <pose>0.3 0 0.15 0 -0 0</pose>
          <geometry>
            <box>
              <size>0.05 0.05 0.05</size>
            </box>
          </geometry>
        </visual>
        <visual name="base_footprint_fixed_joint_lump__gps_link_visual_2">
          <pose>-0.25 0 0.26 0 -0 0</pose>
          <geometry>
            <cylinder>
              <length>0.04</length>
              <radius>0.05</radius>
            </cylinder>
          </geometry>
          <material>
            <script>
              <name>Gazebo/Grey</name>
              <uri>file://media/materials/scripts/gazebo.material</uri>
            </script>
          </material>
        </visual>
        <visual name="base_footprint_fixed_joint_lump__imu_link_visual_3">
          <pose>0 0 0.05 0 -0 0</pose>
          <geometry>
            <cylinder>
              <length>0.04</length>
              <radius>0.05</radius>
            </cylinder>
          </geometry>
          <material>
            <script>
              <name>Gazebo/Grey</name>
              <uri>file://media/materials/scripts/gazebo.material</uri>
            </script>
          </material>
        </visual>
        <visual name="base_footprint_fixed_joint_lump__lidar_stand_visual_4">
          <pose>0.15 0 0.3 0 -0 0</pose>
          <geometry>
            <cylinder>
              <length>0.15</length>
              <radius>0.03</radius>
            </cylinder>
          </geometry>
        </visual>
        <visual name="base_footprint_fixed_joint_lump__laser_frame_visual_5">
          <pose>0.15 0 0.375 0 -0 0</pose>
          <geometry>
            <cylinder>
              <length>0.04</length>
              <radius>0.05</radius>
            </cylinder>
          </geometry>
        </visual>
        <visual name="base_footprint_fixed_joint_lump__stereo_link_visual_6">
          <pose>0.3 0 0.215 0 -0 0</pose>
          <geometry>
            <box>
              <size>0.05 0.05 0.05</size>
            </box>
          </geometry>
        </visual>
        <sensor name="gps_sensor" type="gps">
          <always_on>1</always_on>
          <update_rate>10</update_rate>
          <plugin filename="libgazebo_ros_gps_sensor.so" name="gps_controller">
            <ros>
              <remapping>gps_controller/out:=gps</remapping>
            </ros>
            <frame_name>gps_joint</frame_name>
            <horizontal_position_std_dev>0.0</horizontal_position_std_dev>
            <vertical_position_std_dev>0.0</vertical_position_std_dev>
          </plugin>
          <pose>-0.25 0 0.26 0 -0 0</pose>
          <gps/>
        </sensor>
        <sensor name="imu_sensor" type="imu">
          <always_on>1</always_on>
          <update_rate>10</update_rate>
          <plugin filename="libgazebo_ros_imu_sensor.so" name="imu_controller">
            <ros>
              <remapping>imu_controller/out:=imu</remapping>
            </ros>
            <frame_name>imu_link</frame_name>
          </plugin>
          <pose>0 0 0.05 0 -0 0</pose>
          <imu/>
        </sensor>
        <sensor name="lidar" type="ray">
          <always_on>1</always_on>
          <visualize>0</visualize>
          <update_rate>5</update_rate>
          <ray>
            <scan>
              <horizontal>
                <samples>360</samples>
                <resolution>1</resolution>
                <min_angle>0</min_angle>
                <max_angle>6.28</max_angle>
                <visualize>0</visualize>
              </horizontal>
              <vertical>
                <samples>1</samples>
                <min_angle>0</min_angle>
                <max_angle>0</max_angle>
              </vertical>
            </scan>
            <range>
              <min>0.1</min>
              <max>20</max>
              <resolution>0.015</resolution>
            </range>
            <noise>
              <type>gaussian</type>
              <mean>0</mean>
              <stddev>0.01</stddev>
            </noise>
          </ray>
          <plugin filename="libgazebo_ros_ray_sensor.so" name="scan">
            <ros>
              <remapping>~/out:=scan</remapping>
            </ros>
            <output_type>sensor_msgs/LaserScan</output_type>
            <frame_name>laser_frame</frame_name>
          </plugin>
          <pose>0.15 0 0.375 0 -0 0</pose>
        </sensor>
        <sensor name="camera" type="depth">
          <always_on>1</always_on>
          <update_rate>30</update_rate>
          <visualize>1</visualize>
          <camera name="realsense_depth_camera">
            <horizontal_fov>1.39626</horizontal_fov>
            <image>
              <width>640</width>
              <height>480</height>
              <format>R8G8B8</format>
            </image>
            <clip>
              <near>0.01</near>
              <far>20</far>
            </clip>
            <depth_noise>
              <mean>0.0</mean>
              <stddev>0.005</stddev>
            </depth_noise>
          </camera>
          <plugin filename="libgazebo_ros_camera.so" name="intel_realsense_d430_depth_driver">
            <ros>
              <namespace>d430</namespace>
              <remapping>camera/image_raw:=color/image_raw</remapping>
              <remapping>camera/depth/image_raw:=depth/image_rect_raw</remapping>
              <remapping>camera/camera_info:=camera_info</remapping>
              <remapping>camera/depth/camera_info:=depth/camera_info</remapping>
              <remapping>camera/points:=depth/points</remapping>
            </ros>
            <camera_name>camera</camera_name>
            <frame_name>stereo_link_optical</frame_name>
            <hack_baseline>0.07</hack_baseline>
            <min_depth>0.01</min_depth>
            <max_depth>20.0</max_depth>
          </plugin>
          <pose>0.3 0 0.215 0 -0 0</pose>
        </sensor>
        <self_collide>0</self_collide>
        <enable_wind>0</enable_wind>
        <kinematic>0</kinematic>
      </link>
      <joint name="base_left_wheel_back_joint" type="revolute">
        <pose relative_to="base_footprint">-0.15 0.225 0.05 0 -0 0</pose>
        <parent>base_footprint</parent>
        <child>left_wheel_back_link</child>
        <axis>
          <xyz>0 1 0</xyz>
          <limit>
            <lower>-1e+16</lower>
            <upper>1e+16</upper>
          </limit>
          <dynamics>
            <damping>0.1</damping>
            <friction>0.5</friction>
            <spring_reference>0</spring_reference>
            <spring_stiffness>0</spring_stiffness>
          </dynamics>
        </axis>
      </joint>
      <link name="left_wheel_back_link">
        <pose relative_to="base_left_wheel_back_joint">0 0 0 0 -0 0</pose>
        <inertial>
          <pose>0 0 0 1.57 -0 0</pose>
          <mass>10</mass>
          <inertia>
            <ixx>0.0270833</ixx>
            <ixy>0</ixy>
            <ixz>0</ixz>
            <iyy>0.0270833</iyy>
            <iyz>0</iyz>
            <izz>0.05</izz>
          </inertia>
        </inertial>
        <collision name="left_wheel_back_link_collision">
          <pose>0 0 0 1.57 -0 0</pose>
          <geometry>
            <cylinder>
              <length>0.05</length>
              <radius>0.1</radius>
            </cylinder>
          </geometry>
          <surface>
            <contact>
              <ode/>
            </contact>
            <friction>
              <ode/>
              <torsional>
                <ode/>
              </torsional>
            </friction>
            <bounce/>
          </surface>
          <max_contacts>10</max_contacts>
        </collision>
        <visual name="left_wheel_back_link_visual">
          <pose>0 0 0 1.57 -0 0</pose>
          <geometry>
            <cylinder>
              <length>0.05</length>
              <radius>0.1</radius>
            </cylinder>
          </geometry>
          <material>
            <script>
              <name>Gazebo/White</name>
              <uri>file://media/materials/scripts/gazebo.material</uri>
            </script>
          </material>
        </visual>
        <self_collide>0</self_collide>
        <enable_wind>0</enable_wind>
        <kinematic>0</kinematic>
      </link>
      <joint name="base_left_wheel_front_joint" type="revolute">
        <pose relative_to="base_footprint">0.15 0.225 0.05 0 -0 0</pose>
        <parent>base_footprint</parent>
        <child>left_wheel_front_link</child>
        <axis>
          <xyz>0 1 0</xyz>
          <limit>
            <lower>-1e+16</lower>
            <upper>1e+16</upper>
          </limit>
          <dynamics>
            <damping>0.1</damping>
            <friction>0.5</friction>
            <spring_reference>0</spring_reference>
            <spring_stiffness>0</spring_stiffness>
          </dynamics>
        </axis>
      </joint>
      <link name="left_wheel_front_link">
        <pose relative_to="base_left_wheel_front_joint">0 0 0 0 -0 0</pose>
        <inertial>
          <pose>0 0 0 1.57 -0 0</pose>
          <mass>10</mass>
          <inertia>
            <ixx>0.0270833</ixx>
            <ixy>0</ixy>
            <ixz>0</ixz>
            <iyy>0.0270833</iyy>
            <iyz>0</iyz>
            <izz>0.05</izz>
          </inertia>
        </inertial>
        <collision name="left_wheel_front_link_collision">
          <pose>0 0 0 1.57 -0 0</pose>
          <geometry>
            <cylinder>
              <length>0.05</length>
              <radius>0.1</radius>
            </cylinder>
          </geometry>
          <surface>
            <contact>
              <ode/>
            </contact>
            <friction>
              <ode/>
              <torsional>
                <ode/>
              </torsional>
            </friction>
            <bounce/>
          </surface>
          <max_contacts>10</max_contacts>
        </collision>
        <visual name="left_wheel_front_link_visual">
          <pose>0 0 0 1.57 -0 0</pose>
          <geometry>
            <cylinder>
              <length>0.05</length>
              <radius>0.1</radius>
            </cylinder>
          </geometry>
          <material>
            <script>
              <name>Gazebo/White</name>
              <uri>file://media/materials/scripts/gazebo.material</uri>
            </script>
          </material>
        </visual>
        <self_collide>0</self_collide>
        <enable_wind>0</enable_wind>
        <kinematic>0</kinematic>
      </link>
      <joint name="base_right_wheel_back_joint" type="revolute">
        <pose relative_to="base_footprint">-0.15 -0.225 0.05 0 -0 0</pose>
        <parent>base_footprint</parent>
        <child>right_wheel_back_link</child>
        <axis>
          <xyz>0 1 0</xyz>
          <limit>
            <lower>-1e+16</lower>
            <upper>1e+16</upper>
          </limit>
          <dynamics>
            <damping>0.1</damping>
            <friction>0.5</friction>
            <spring_reference>0</spring_reference>
            <spring_stiffness>0</spring_stiffness>
          </dynamics>
        </axis>
      </joint>
      <link name="right_wheel_back_link">
        <pose relative_to="base_right_wheel_back_joint">0 0 0 0 -0 0</pose>
        <inertial>
          <pose>0 0 0 -1.57 0 0</pose>
          <mass>10</mass>
          <inertia>
            <ixx>0.0270833</ixx>
            <ixy>0</ixy>
            <ixz>0</ixz>
            <iyy>0.0270833</iyy>
            <iyz>0</iyz>
            <izz>0.05</izz>
          </inertia>
        </inertial>
        <collision name="right_wheel_back_link_collision">
          <pose>0 0 0 -1.57 0 0</pose>
          <geometry>
            <cylinder>
              <length>0.05</length>
              <radius>0.1</radius>
            </cylinder>
          </geometry>
          <surface>
            <contact>
              <ode/>
            </contact>
            <friction>
              <ode/>
              <torsional>
                <ode/>
              </torsional>
            </friction>
            <bounce/>
          </surface>
          <max_contacts>10</max_contacts>
        </collision>
        <visual name="right_wheel_back_link_visual">
          <pose>0 0 0 -1.57 0 0</pose>
          <geometry>
            <cylinder>
              <length>0.05</length>
              <radius>0.1</radius>
            </cylinder>
          </geometry>
          <material>
            <script>
              <name>Gazebo/White</name>
              <uri>file://media/materials/scripts/gazebo.material</uri>
            </script>
          </material>
        </visual>
        <self_collide>0</self_collide>
        <enable_wind>0</enable_wind>
        <kinematic>0</kinematic>
      </link>
      <joint name="base_right_wheel_front_joint" type="revolute">
        <pose relative_to="base_footprint">0.15 -0.225 0.05 0 -0 0</pose>
        <parent>base_footprint</parent>
        <child>right_wheel_front_link</child>
        <axis>
          <xyz>0 1 0</xyz>
          <limit>
            <lower>-1e+16</lower>
            <upper>1e+16</upper>
          </limit>
          <dynamics>
            <damping>0.1</damping>
            <friction>0.5</friction>
            <spring_reference>0</spring_reference>
            <spring_stiffness>0</spring_stiffness>
          </dynamics>
        </axis>
      </joint>
      <link name="right_wheel_front_link">
        <pose relative_to="base_right_wheel_front_joint">0 0 0 0 -0 0</pose>
        <inertial>
          <pose>0 0 0 -1.57 0 0</pose>
          <mass>10</mass>
          <inertia>
            <ixx>0.0270833</ixx>
            <ixy>0</ixy>
            <ixz>0</ixz>
            <iyy>0.0270833</iyy>
            <iyz>0</iyz>
            <izz>0.05</izz>
          </inertia>
        </inertial>
        <collision name="right_wheel_front_link_collision">
          <pose>0 0 0 -1.57 0 0</pose>
          <geometry>
            <cylinder>
              <length>0.05</length>
              <radius>0.1</radius>
            </cylinder>
          </geometry>
          <max_contacts>10</max_contacts>
          <surface>
            <contact>
              <ode/>
            </contact>
            <bounce/>
            <friction>
              <torsional>
                <ode/>
              </torsional>
              <ode/>
            </friction>
          </surface>
        </collision>
        <visual name="right_wheel_front_link_visual">
          <pose>0 0 0 -1.57 0 0</pose>
          <geometry>
            <cylinder>
              <length>0.05</length>
              <radius>0.1</radius>
            </cylinder>
          </geometry>
        </visual>
        <self_collide>0</self_collide>
        <enable_wind>0</enable_wind>
        <kinematic>0</kinematic>
      </link>
      <plugin filename="libgazebo_ros_diff_drive.so" name="diff_drive">
        <num_wheel_pairs>2</num_wheel_pairs>
        <left_joint>base_left_wheel_front_joint</left_joint>
        <right_joint>base_right_wheel_front_joint</right_joint>
        <left_joint>base_left_wheel_back_joint</left_joint>
        <right_joint>base_right_wheel_back_joint</right_joint>
        <wheel_separation>0.45</wheel_separation>
        <wheel_diameter>0.2</wheel_diameter>
        <max_wheel_torque>10</max_wheel_torque>
        <max_wheel_acceleration>1.0</max_wheel_acceleration>
        <publish_odom>1</publish_odom>
        <publish_odom_tf>1</publish_odom_tf>
        <publish_wheel_tf>0</publish_wheel_tf>
        <odometry_frame>odom</odometry_frame>
        <robot_base_frame>base_footprint</robot_base_frame>
      </plugin>
      <static>0</static>
      <plugin filename="libgazebo_ros_joint_state_publisher.so" name="gazebo_ros_joint_state_publisher">
        <update_rate>10</update_rate>
        <joint_name>base_left_wheel_front_joint</joint_name>
        <joint_name>base_left_wheel_back_joint</joint_name>
        <joint_name>base_right_wheel_front_joint</joint_name>
        <joint_name>base_right_wheel_back_joint</joint_name>
      </plugin>
      <pose>0 0 0 0 -0 0</pose>
    </model>
    <model name="unit_box">
      <pose>2.93941 -0.010716 0.5 0 -0 0</pose>
      <link name="link">
        <inertial>
          <mass>1</mass>
          <inertia>
            <ixx>0.166667</ixx>
            <ixy>0</ixy>
            <ixz>0</ixz>
            <iyy>0.166667</iyy>
            <iyz>0</iyz>
            <izz>0.166667</izz>
          </inertia>
          <pose>0 0 0 0 -0 0</pose>
        </inertial>
        <collision name="collision">
          <geometry>
            <box>
              <size>1 1 1</size>
            </box>
          </geometry>
          <max_contacts>10</max_contacts>
          <surface>
            <contact>
              <ode/>
            </contact>
            <bounce/>
            <friction>
              <torsional>
                <ode/>
              </torsional>
              <ode/>
            </friction>
          </surface>
        </collision>
        <visual name="visual">
          <geometry>
            <box>
              <size>1 1 1</size>
            </box>
          </geometry>
          <material>
            <script>
              <name>Gazebo/Grey</name>
              <uri>file://media/materials/scripts/gazebo.material</uri>
            </script>
          </material>
        </visual>
        <self_collide>0</self_collide>
        <enable_wind>0</enable_wind>
        <kinematic>0</kinematic>
      </link>
    </model>
    <state world_name="default">
      <sim_time>16 764000000</sim_time>
      <real_time>17 772210788</real_time>
      <wall_time>1754664731 149906094</wall_time>
      <iterations>16764</iterations>
      <model name="ground_plane">
        <pose>0 0 0 0 -0 0</pose>
        <scale>1 1 1</scale>
        <link name="link">
          <pose>0 0 0 0 -0 0</pose>
          <velocity>0 0 0 0 -0 0</velocity>
          <acceleration>0 0 0 0 -0 0</acceleration>
          <wrench>0 0 0 0 -0 0</wrench>
        </link>
      </model>
      <model name="my_robot">
        <pose>-5.6e-05 -2e-06 0.05002 0 -0 6e-06</pose>
        <scale>1 1 1</scale>
        <link name="base_footprint">
          <pose>-5.6e-05 -2e-06 0.05002 0 -0 6e-06</pose>
          <velocity>-3e-06 0 -0 0 -0 0</velocity>
          <acceleration>0 -0 0 -1e-06 1e-06 0</acceleration>
          <wrench>4e-06 -1e-06 3e-06 0 -0 0</wrench>
        </link>
        <link name="left_wheel_back_link">
          <pose>-0.150057 0.224998 0.10002 -2e-06 -0.000522 6e-06</pose>
          <velocity>-3e-06 0 -0 5e-06 -3.3e-05 0</velocity>
          <acceleration>0 -0 0 -1.2e-05 4e-06 0</acceleration>
          <wrench>4e-06 -4e-06 2e-06 0 -0 0</wrench>
        </link>
        <link name="left_wheel_front_link">
          <pose>0.149943 0.224999 0.10002 -1e-06 -0.000548 6e-06</pose>
          <velocity>-3e-06 0 -0 4e-06 -3.3e-05 0</velocity>
          <acceleration>0 -0 0 -1.3e-05 3e-06 -0</acceleration>
          <wrench>3e-06 -3e-06 2e-06 0 -0 0</wrench>
        </link>
        <link name="right_wheel_back_link">
          <pose>-0.150054 -0.225002 0.10002 2e-06 -0.000511 6e-06</pose>
          <velocity>-3e-06 -0 -0 -5e-06 -3.4e-05 0</velocity>
          <acceleration>0 0 0 1.2e-05 4e-06 -0</acceleration>
          <wrench>4e-06 4e-06 2e-06 0 -0 0</wrench>
        </link>
        <link name="right_wheel_front_link">
          <pose>0.149946 -0.225001 0.10002 1e-06 -0.000558 6e-06</pose>
          <velocity>-3e-06 -0 -0 -4e-06 -3.3e-05 -0</velocity>
          <acceleration>0 0 0 1.3e-05 3e-06 0</acceleration>
          <wrench>3e-06 3e-06 2e-06 0 -0 0</wrench>
        </link>
      </model>
      <model name="unit_box">
        <pose>2.93941 -0.010716 0.5 0 -0 0</pose>
        <scale>1 1 1</scale>
        <link name="link">
          <pose>2.93941 -0.010716 0.5 0 -0 0</pose>
          <velocity>0 0 0 0 -0 0</velocity>
          <acceleration>-0.004709 -9.78112 9.78158 0.712677 -0.009414 -4.3e-05</acceleration>
          <wrench>-0.004709 -9.78112 9.78158 0 -0 0</wrench>
        </link>
      </model>
      <light name="sun">
        <pose>0 0 10 0 -0 0</pose>
      </light>
    </state>
    <gui fullscreen="0">
      <camera name="user_camera">
        <pose>-6.6982 -6.13061 37.2398 0 1.33564 0.128196</pose>
        <view_controller>orbit</view_controller>
        <projection_type>perspective</projection_type>
      </camera>
    </gui>
  </world>
</sdf>
